<?xml version="1.0" ?>
<!-- =================================================================================== -->
<!-- |    This document was autogenerated by xacro from base_mp500.urdf.xacro          | -->
<!-- |    EDITING THIS FILE BY HAND IS NOT RECOMMENDED                                 | -->
<!-- =================================================================================== -->
<robot name="base_mp500" xmlns:xacro="http://www.ros.org/wiki/xacro">
  <!--+++++++++ Material +++++++++-->
  <material name="Black">
    <color rgba="0.0 0.0 0.0 1.0"/>
  </material>
  <material name="Blue">
    <color rgba="0.0 0.0 0.8 1.0"/>
  </material>
  <material name="Green">
    <color rgba="0.0 0.8 0.0 1.0"/>
  </material>
  <material name="Grey">
    <color rgba="0.7 0.7 0.7 1.0"/>
  </material>
  <material name="Grey2">
    <color rgba="0.9 0.9 0.9 1.0"/>
  </material>
  <material name="Red">
    <color rgba="0.8 0.0 0.0 1.0"/>
  </material>
  <material name="White">
    <color rgba="1.0 1.0 1.0 1.0"/>
  </material>
  <material name="Yellow">
    <color rgba="1.0 1.0 0 1.0"/>
  </material>
  <material name="LightGrey">
    <color rgba="0.7 0.7 0.7 1.0"/>
  </material>
  <material name="DarkGrey">
    <color rgba="0.4 0.4 0.4 1.0"/>
  </material>
  <material name="DarkGolden">
    <color rgba="0.4 0.4 0.3 1.0"/>
  </material>
  <!-- Base Link -->
  <gazebo reference="base_footprint">
    <material value="Gazebo/Grey"/>
  </gazebo>
  <gazebo reference="base_link">
    <gravity>true</gravity>
    <material value="Gazebo/Grey"/>
  </gazebo>
  <!-- Left Wheel -->
  <gazebo reference="wheel_left_link">
    <gravity>true</gravity>
    <mu1>100.5</mu1>
    <mu2>100.5</mu2>
    <kp>1000000.0</kp>
    <kd>100.0</kd>
    <fdir1>0 0 1</fdir1>
    <material value="Gazebo/Grey"/>
  </gazebo>
  <!-- Right Wheel -->
  <gazebo reference="wheel_right_link">
    <gravity>true</gravity>
    <mu1>100.5</mu1>
    <mu2>100.5</mu2>
    <kp>1000000.0</kp>
    <kd>100.0</kd>
    <fdir1>0 0 1</fdir1>
    <material value="Gazebo/Grey"/>
  </gazebo>
  <!-- Castor -->
  <gazebo reference="hanger">
    <gravity>true</gravity>
    <mu1>0.1</mu1>
    <mu2>0.1</mu2>
    <kp>1000000.0</kp>
    <kd>100.0</kd>
    <material value="Gazebo/Grey"/>
  </gazebo>
  <!--<gazebo reference="castor_front">
          <gravity>true</gravity>
          <mu1>0.1</mu1>
          <mu2>0.1</mu2>
          <kp>1000000.0</kp>
          <kd>100.0</kd>
          <material value="Gazebo/Grey"/>
      </gazebo>-->
  <transmission name="wheel_left_trans">
    <type>transmission_interface/SimpleTransmission</type>
    <joint name="wheel_left_joint">
      <hardwareInterface>hardware_interface/VelocityJointInterface</hardwareInterface>
    </joint>
    <actuator name="wheel_left_motor">
      <hardwareInterface>hardware_interface/EffortJointInterface</hardwareInterface>
      <mechanicalReduction>1</mechanicalReduction>
    </actuator>
  </transmission>
  <transmission name="wheel_right_trans">
    <type>transmission_interface/SimpleTransmission</type>
    <joint name="wheel_right_joint">
      <hardwareInterface>hardware_interface/VelocityJointInterface</hardwareInterface>
    </joint>
    <actuator name="wheel_right_motor">
      <hardwareInterface>hardware_interface/EffortJointInterface</hardwareInterface>
      <mechanicalReduction>1</mechanicalReduction>
    </actuator>
  </transmission>
  <!--++++++++++++++++++base_link+++++++++++++++++++++-->
  <joint name="base_footprint_joint" type="fixed">
    <origin rpy="0 0 0" xyz="0 0 0"/>
    <parent link="base_footprint"/>
    <child link="base_link"/>
  </joint>
  <link name="base_footprint">
    <visual>
      <origin rpy="0 0 0" xyz="0 0 0"/>
      <geometry>
        <box size="0.001 0.001 0.001"/>
      </geometry>
    </visual>
  </link>
  <link name="base_link">
    <inertial>
      <mass value="1"/>
      <!--<origin xyz="0 0 0.216" rpy="0 0 0"/>-->
      <!--<inertia ixx="0.54" ixy="0.0" ixz="0.0" iyy="1.08" iyz="0.0" izz="1.23" />-->
      <inertia ixx="1" ixy="0.0" ixz="0.0" iyy="1" iyz="0.0" izz="1"/>
    </inertial>
    <visual name="body">
      <!--origin xyz="0.0 0.0 0.234" rpy="0 0 1.57" /-->
      <!-- for cylinder -->
      <origin rpy="0 0 -1.57" xyz="-0.160 0.0 0.09"/>
      <!-- for STL -->
      <geometry>
        <mesh filename="package://mp500lwa4d_description/meshes/mp500/MP500-BODY.STL" scale="0.01 0.01 0.01"/>
        <!--cylinder length="0.381" radius="0.2545"/-->
        <!--box size="0.445 0.277 0.17"/-->
      </geometry>
      <material name="Grey"/>
    </visual>
    <collision name="body_collision">
      <origin rpy="0 0 -1.57" xyz="0 0 0.216"/>
      <geometry>
        <box size="0.400 0.676 0.300"/>
        <!--cylinder length="0.381" radius="0.2545"/-->
      </geometry>
    </collision>
  </link>
  <!--+++++++++++++++wheel_left_link++++++++++++++++++-->
  <link name="wheel_left_link" type="wheel">
    <inertial>
      <mass value="1"/>
      <origin rpy="0 0 0" xyz="0 0 0"/>
      <inertia ixx="0.0045" ixy="0" ixz="0" iyy="0.0078" iyz="0" izz="0.0045"/>
    </inertial>
    <visual>
      <origin rpy="0 0 -1.57" xyz="0 0 0"/>
      <geometry>
        <mesh filename="package://mp500lwa4d_description/meshes/mp500/MP500-WHEEL.STL" scale="0.01 0.01 0.01"/>
      </geometry>
      <material name="Black"/>
    </visual>
    <collision>
      <origin rpy="0 1.57 -1.57" xyz="0 0 0"/>
      <geometry>
        <cylinder length="0.085" radius="0.125"/>
      </geometry>
    </collision>
  </link>
  <!--+++++++++++++++wheel_left_joint+++++++++++++++++-->
  <joint name="wheel_left_joint" type="continuous">
    <origin rpy="0 0 0" xyz="-0.155 0.255 0.13"/>
    <axis xyz="0 1 0"/>
    <limit effort="500" velocity="5"/>
    <dynamics damping="0.0" friction="0.0"/>
    <parent link="base_link"/>
    <child link="wheel_left_link"/>
  </joint>
  <!--+++++++++++++++wheel_right_link+++++++++++++++++-->
  <!--Mesh Volume is 3587.704102
Mesh Surface is 1876.550415
Thin shell barycenter -25.340059 -0.000027 4.499997
Center of Mass is -25.340000 -0.000164 4.500009
Inertia Tensor is :
| 322624.937500 -0.068522 -1.293689 |
| -0.068522 179104.328125 -1.342927 |
| -1.293689 -1.342927 179079.796875 |
Principal axes are :
| 1.000000 -0.000000 0.000009 |
| -0.000000 0.998514 0.054499 |
| -0.000009 -0.054499 0.998514 |
axis momenta are :
| 322624.937500 179104.406250 179079.718750 |
Mesh Volume is 0.000000
Mesh Surface is 0.000019
Thin shell barycenter -0.002534 -0.000000 0.000450
Center of Mass is -0.002534 -0.000000 0.000450
Inertia Tensor is :
| 0.000000 -0.000000 -0.000000 |
| -0.000000 0.000000 -0.000000 |
| -0.000000 -0.000000 0.000000 |
Principal axes are :
| 1.000000 -0.000000 0.000009 |
| -0.000000 0.998526 0.054276 |
| -0.000009 -0.054276 0.998526 |
axis momenta are :
| 0.000000 0.000000 0.000000 | -->
  <link name="wheel_right_link" type="wheel">
    <inertial>
      <mass value="1"/>
      <origin rpy="0 0 0" xyz="0 0 0"/>
      <!--inertia ixx="0.0051" ixy="0" ixz="0" iyy="0.0051" iyz="0" izz="0.009" /-->
      <inertia ixx="0.0045" ixy="0" ixz="0" iyy="0.0078" iyz="0" izz="0.0045"/>
    </inertial>
    <visual>
      <origin rpy="0 0 -1.57" xyz="0 0 0"/>
      <geometry>
        <mesh filename="package://mp500lwa4d_description/meshes/mp500/MP500-WHEEL.STL" scale="0.01 0.01 0.01"/>
      </geometry>
      <material name="Black"/>
    </visual>
    <collision>
      <origin rpy="0 1.57 -1.57" xyz="0 0 0"/>
      <geometry>
        <cylinder length="0.085" radius="0.125"/>
      </geometry>
    </collision>
  </link>
  <!--++++++++++++wheel_right_joint++++++++++++++-->
  <joint name="wheel_right_joint" type="continuous">
    <origin rpy="0 0 0" xyz="-0.155 -0.255 0.13"/>
    <axis xyz="0 1 0"/>
    <limit effort="500" velocity="5"/>
    <dynamics damping="0.0" friction="0.0"/>
    <parent link="base_link"/>
    <child link="wheel_right_link"/>
  </joint>
  <!--+++++++++++++++ wheel_hanger+++++++++++++++-->
  <link name="hanger">
    <inertial>
      <mass value="0.01"/>
      <origin rpy="0 0 0" xyz="0 0 0"/>
      <inertia ixx="0.0013" ixy="0" ixz="0" iyy="0.0013" iyz="0" izz="0.0013"/>
    </inertial>
    <visual>
      <origin rpy="0 0 -1.57" xyz="0 0 0"/>
      <geometry>
        <mesh filename="package://mp500lwa4d_description/meshes/mp500/HANGER-WHEEL.STL" scale="0.01 0.01 0.01"/>
      </geometry>
      <material name="Grey"/>
    </visual>
    <collision>
      <origin rpy="0 0 -1.57" xyz="0 0 0"/>
      <geometry>
        <mesh filename="package://mp500lwa4d_description/meshes/mp500/HANGER-WHEEL.STL" scale="0.01 0.01 0.01"/>
      </geometry>
    </collision>
  </link>
  <joint name="hanger_joint" type="fixed">
    <origin rpy="0 0 0" xyz="0.255 0 0.11"/>
    <axis xyz="0 0 1"/>
    <parent link="base_link"/>
    <child link="hanger"/>
  </joint>
</robot>

